{"url": "https://api.github.com/repos/Significant-Gravitas/Auto-GPT/issues/2782", "repository_url": "https://api.github.com/repos/Significant-Gravitas/Auto-GPT", "labels_url": "https://api.github.com/repos/Significant-Gravitas/Auto-GPT/issues/2782/labels{/name}", "comments_url": "https://api.github.com/repos/Significant-Gravitas/Auto-GPT/issues/2782/comments", "events_url": "https://api.github.com/repos/Significant-Gravitas/Auto-GPT/issues/2782/events", "html_url": "https://github.com/Significant-Gravitas/Auto-GPT/issues/2782", "id": 1677953038, "node_id": "I_kwDOJKSTjM5kA4gO", "number": 2782, "title": "Catalog of many inconsistencies on the AI. V0.2", "user": {"login": "makrse", "id": 131285038, "node_id": "U_kgDOB9NALg", "avatar_url": "https://avatars.githubusercontent.com/u/131285038?v=4", "gravatar_id": "", "url": "https://api.github.com/users/makrse", "html_url": "https://github.com/makrse", "followers_url": "https://api.github.com/users/makrse/followers", "following_url": "https://api.github.com/users/makrse/following{/other_user}", "gists_url": "https://api.github.com/users/makrse/gists{/gist_id}", "starred_url": "https://api.github.com/users/makrse/starred{/owner}{/repo}", "subscriptions_url": "https://api.github.com/users/makrse/subscriptions", "organizations_url": "https://api.github.com/users/makrse/orgs", "repos_url": "https://api.github.com/users/makrse/repos", "events_url": "https://api.github.com/users/makrse/events{/privacy}", "received_events_url": "https://api.github.com/users/makrse/received_events", "type": "User", "site_admin": false}, "labels": [], "state": "open", "locked": false, "assignee": null, "assignees": [], "milestone": null, "comments": 5, "created_at": "2023-04-21T06:59:23Z", "updated_at": "2023-04-24T15:01:15Z", "closed_at": null, "author_association": "NONE", "active_lock_reason": null, "body": "### Duplicates\r\n\r\n- [ ] I have searched the existing issues\r\n- [x] Try put every common encounter issues and sumarize.\r\n- [ ] Rely on the past posted issues and try to replicate if still happen again and report it on time.\r\n- [x] Try every scenario possible to catch bad arguments that the AI used to be corrected in a future patch.\r\n### Summary \ud83d\udca1\r\n\r\n**I want to write all the issues I encounter when trying understand how autogpt works:**\r\n\r\n1\r\n--\r\nTheres error when auto-gpt trying to clone a git  :\r\n\r\n   - NEXT ACTION:  COMMAND = google ARGUMENTS = {'input': 'repository URL for <repository_name>'}\r\n   \r\nThe AI uses literally  'repository URL' like an actual URL, that makes an infinite loop trying to clone a respository.\r\n\r\n------------------------------------------------------------------------------------------------------------------------\r\n2\r\n--\r\nSimilar error :\r\n\r\n     - NEXT ACTION:  COMMAND = clone_repository ARGUMENTS = {'repository_url': '<repository_url>', 'clone_path': '<clone_path>'}\r\n\r\nThe AI does not take actual <repository_url>, and the <clone_path> literally as a path that does not exist, making it another infinite loop.\r\n\r\n-------------------------------------------------------------------------------------------------------------------------\r\n3\r\n--\r\nWhen call it to analize self code :\r\n\r\n     - NEXT ACTION:  COMMAND = analyze_code ARGUMENTS = {'code': '<insert self code here>'}\r\n\r\nIt takes literally <insert self code here> as an argumment to the own code in witch does not exist such file and cannot determine this is a major failure despite to mention it before after 2 failed attempts to do not repeat same action.\r\n\r\n-------------------------------------------------------------------------------------------------------------------------\r\n4\r\n--\r\nWhen Json object invalid: related to https://github.com/Significant-Gravitas/Auto-GPT/issues/21\r\n\r\n    - NEXT ACTION:  COMMAND = Error: ARGUMENTS = Missing 'command' object in JSON\r\n    - SYSTEM:  Command Error: threw the following error: Missing 'command' object in JSON\r\n\r\nWhen try to on his own to fix this bug it does not be able to do it making another infinite loop.\r\n\r\n---------------------------------------------------------------------------------------------------------------------------\r\n5\r\n--\r\nWhen after many fail attemps get the actual URL of an git :\r\n\r\n   - NEXT ACTION:  COMMAND = clone_repository ARGUMENTS = {'repository_url': 'https://github.com/ElementAI/ggml.git', 'clone_path': '/app/nbs/ai_platform/auto_gpt_workspace/ggml'}\r\nSYSTEM:  Command clone_repository returned: Error: Attempted to access path 'D:\\app\\nbs\\ai_platform\\auto_gpt_workspace\\ggml' outside of workspace 'D:\\AI\\Auto-GPT\\auto_gpt_workspace'.\r\n\r\nIt does not aware the only path that can have access its auto_gpt_workspace, that its because the AI copy other sources files path or literally \"disk:/path/to/this/\" , making it having cause failures trying many arguments to realize the right path, sometimes does not. \r\n\r\n----------------------------------------------------------------------------------------------------------------------------\r\n6. The env file even changed the default search motor to firefox, opera, ME, it still use chrome.\r\n7. Giving permission to work outside of workspace also does not work.\r\n8. Giving the username of Github and \" personal access token (classic)' as a key does not work.\r\n-----------------------------------------------------------------------------------------------------------------------------\r\n9\r\n--\r\n When try to analize code:\r\n\r\n  - NEXT ACTION:  COMMAND = analyze_code ARGUMENTS = {'code': '<full_code_string>'}\r\n\r\nIt literally takes the request to find a way to download a unkown package to analize code, using \"analize_code_package\" as an actual sources to analize, and takes code: <full_code_string> literally as a hole, in witch the code to be analize its : literally <full_code_string>as a phrase and not an actual file with real code inside.\r\n\r\n-----------------------------------------------------------------------------------------------------------------------------\r\n10\r\n--\r\n When try to analize an actual py file :\r\n\r\n  - Use the 'execute_python_file' command to run the 'discord_analysis.py' script.\r\nCRITICISM:  I need to make sure that the script is properly executed and that any errors are handled appropriately.\r\n  - NEXT ACTION:  COMMAND = execute_python_file ARGUMENTS = {'filename': 'Somecode_analysis.py'}\r\n  - Executing file 'Somecode_analysis.py' in workspace 'D:\\AI\\Auto-GPT\\auto_gpt_workspace'\r\nCould not run the script in a container. If you haven't already, please install Docker https://docs.docker.com/get-docker/\r\nSYSTEM:  Command execute_python_file returned: Error: Error while fetching server API version: (2, 'CreateFile', 'System could not find the file.')\r\n\r\nTheres have issues when try to analize a file itself.\r\n\r\n-----------------------------------------------------------------------------------------------------------------------------\r\n11\r\n--\r\n When try to search, read, execute a concrete file.\r\n\r\n   - NEXT ACTION:  COMMAND = search_files ARGUMENTS = {'directory': '.', 'filename': 'Somecode_analysis.py'}\r\n   - SYSTEM:  Command search_files returned: Error: search_files() got an unexpected keyword argument 'filename'\r\n  \r\n    - NEXT ACTION:  COMMAND = read_file ARGUMENTS = {'filename': '<filename>'}\r\n    - SYSTEM:  Command read_file returned: Error: [Errno 22] Invalid argument: 'D:\\\\AI\\\\Auto-GPT\\\\auto_gpt_workspace\\\\<filename>'\r\n\r\n    - NEXT ACTION:  COMMAND = execute_python_file ARGUMENTS = {'filename': '<filename>'}\r\n     Executing file '<filename>' in workspace 'D:\\AI\\Auto-GPT\\auto_gpt_workspace'\r\n    - SYSTEM:  Command execute_python_file returned: Error: Invalid file type. Only .py files are allowed.\r\n\r\n\r\nThe main issue it's take '<filename>' literally as a actual file that does not exist and do not able to be aware or able to find the right file, even if the file being found, theres some bad argument, incluiding dont be able to recongnize the file type even with the file extension.\r\n\r\n------------------------------------------------------------------------------------------------------------------------------\r\n12\r\n--\r\n Major flag trying to let own Auto-GPT to run self code test :\r\n\r\n**First scenario:**\r\nTHOUGHTS:  I should write tests for my code to ensure that it is working as expected.\r\nREASONING:  Writing tests will help me identify any errors in my code and ensure that it is working as expected.\r\nCRITICISM:  I need to make sure that my tests are comprehensive and cover all possible scenarios.\r\nNEXT ACTION:  COMMAND = write_tests ARGUMENTS = {'code': '<full_code_string>', 'focus': '<list_of_focus_areas>'}\r\nSYSTEM:  Command write_tests returned: Error: The model: `gpt-4` does not exist\r\n\r\n**Second scenario:**\r\nTHOUGHTS:  I should try to get suggestions for improving my code.\r\nCRITICISM:  I need to make sure that the suggestions are relevant and applicable to my code.\r\nNEXT ACTION:  COMMAND = improve_code ARGUMENTS = {'suggestions': '<list_of_suggestions>', 'code': '<full_code_string>'\r\n\r\n\r\nThe main point its AI continue trying to execute bad code argument in order to analize an non existent code. even with not having gp4 model key, it incluides 3.5 too.\r\n\r\n-------------------------------------------------------------------------------------------------------------------------------\r\n13\r\n--\r\nWhen try to do write an existent file :\r\n\r\n    - NEXT ACTION:  COMMAND = write_to_file ARGUMENTS = {'filename': 'phrases.txt', 'text': 'an example of phrases'}\r\n\r\n\r\n**First scenario:**\r\nIt seems when re open the auto-gpt to continue the task discovered theres already made file, then when try to make an update of the file uses \"write_to_file \" argument but gives error, so then after many fail attempts use the \"append_to_file\" to rewrite the file.\r\n\r\n**Second scenario:**\r\nWhen happen the same and does not be able to recall itself to use  \"append_to_file\" to update the file with new stuff, begin an infinite loop on make use between \"delete_file\" and \"write_to_file\" commands.\r\n\r\n**Third scenario:**\r\nWhen happen to after delete and made new file on a loop also emerge a big major failure trying to use again already searched sources on the web, making **the loop of** : DELETE FILE ---- SEARCH GOOGLE SOURCE----WRITE FILE, this loop can seems its progresing to done the task but its a false-positive waste of money loop.\r\n\r\n**Cause :** : \r\nFailure to use write_to_file to an existent file to update content :\r\n - SYSTEM:  Command write_to_file returned: Error: File has already been updated.\r\n\r\n\r\n\r\n### Motivation \ud83d\udd26\r\n\r\nTrying to provide more feedback to improve.", "reactions": {"url": "https://api.github.com/repos/Significant-Gravitas/Auto-GPT/issues/2782/reactions", "total_count": 0, "+1": 0, "-1": 0, "laugh": 0, "hooray": 0, "confused": 0, "heart": 0, "rocket": 0, "eyes": 0}, "timeline_url": "https://api.github.com/repos/Significant-Gravitas/Auto-GPT/issues/2782/timeline", "performed_via_github_app": null, "state_reason": null}