{"url": "https://api.github.com/repos/Significant-Gravitas/Auto-GPT/issues/1614", "repository_url": "https://api.github.com/repos/Significant-Gravitas/Auto-GPT", "labels_url": "https://api.github.com/repos/Significant-Gravitas/Auto-GPT/issues/1614/labels{/name}", "comments_url": "https://api.github.com/repos/Significant-Gravitas/Auto-GPT/issues/1614/comments", "events_url": "https://api.github.com/repos/Significant-Gravitas/Auto-GPT/issues/1614/events", "html_url": "https://github.com/Significant-Gravitas/Auto-GPT/issues/1614", "id": 1669459585, "node_id": "I_kwDOJKSTjM5jge6B", "number": 1614, "title": "New Issue since re-org Pull: in fix_and_parse_json return json.loads(maybe_fixed_json)", "user": {"login": "OannesGPT", "id": 129926953, "node_id": "U_kgDOB76HKQ", "avatar_url": "https://avatars.githubusercontent.com/u/129926953?v=4", "gravatar_id": "", "url": "https://api.github.com/users/OannesGPT", "html_url": "https://github.com/OannesGPT", "followers_url": "https://api.github.com/users/OannesGPT/followers", "following_url": "https://api.github.com/users/OannesGPT/following{/other_user}", "gists_url": "https://api.github.com/users/OannesGPT/gists{/gist_id}", "starred_url": "https://api.github.com/users/OannesGPT/starred{/owner}{/repo}", "subscriptions_url": "https://api.github.com/users/OannesGPT/subscriptions", "organizations_url": "https://api.github.com/users/OannesGPT/orgs", "repos_url": "https://api.github.com/users/OannesGPT/repos", "events_url": "https://api.github.com/users/OannesGPT/events{/privacy}", "received_events_url": "https://api.github.com/users/OannesGPT/received_events", "type": "User", "site_admin": false}, "labels": [], "state": "open", "locked": false, "assignee": null, "assignees": [], "milestone": null, "comments": 2, "created_at": "2023-04-15T15:42:32Z", "updated_at": "2023-04-15T15:55:10Z", "closed_at": null, "author_association": "NONE", "active_lock_reason": null, "body": "### Duplicates\n\n- [X] I have searched the existing issues\n\n### Steps to reproduce \ud83d\udd79\n\nI experience an error I hadn't before the re-organsation error\r\n\r\nI set as first goal to read my instructions: \"Read {''file'': instructions.txt} and follow and follow any instructions in that\"\r\n\r\nInstructions.txt contains:\r\n`Develop a game app heads and tails in python that works offline in the browser, the Python module where to save this code will be called `main.py'. Here are the game rules: \"In the game of Heads and Tails, a coin is flipped and the player must guess whether it will land on heads or tails. If the player guesses correctly, they win. If they guess incorrectly, they lose. The game can be played with any number of players, and the winner is the player with the highest number of correct guesses at the end of the designated number of rounds. In the event of a tie, the players can either share the victory or play a tiebreaker round.\"\r\n\r\nUse your commands such as write_file, append, evaluate, execute, improve.\r\nDo not delete the .txt file instructions.txt by any means\r\n`\n\n### Current behavior \ud83d\ude2f\n\n`Error:\r\n  Traceback (most recent call last):\r\n  File \"C:\\Users\\Hannes\\Documents\\GitHub\\Auto-GPT\\autogpt\\json_fixes\\parsing.py\", line 105, in fix_and_parse_json\r\n    return json.loads(maybe_fixed_json)\r\n           ^^^^^^^^^^^^^^^^^^^^^^^^^^^^\r\n  File \"C:\\Users\\Hannes\\AppData\\Local\\Programs\\Python\\Python311\\Lib\\json\\__init__.py\", line 346, in loads\r\n    return _default_decoder.decode(s)\r\n           ^^^^^^^^^^^^^^^^^^^^^^^^^^\r\n  File \"C:\\Users\\Hannes\\AppData\\Local\\Programs\\Python\\Python311\\Lib\\json\\decoder.py\", line 337, in decode\r\n    obj, end = self.raw_decode(s, idx=_w(s, 0).end())\r\n               ^^^^^^^^^^^^^^^^^^^^^^^^^^^^^^^^^^^^^^\r\n  File \"C:\\Users\\Hannes\\AppData\\Local\\Programs\\Python\\Python311\\Lib\\json\\decoder.py\", line 353, in raw_decode\r\n    obj, end = self.scan_once(s, idx)\r\n               ^^^^^^^^^^^^^^^^^^^^^^\r\njson.decoder.JSONDecodeError: Expecting property name enclosed in double quotes: line 13 column 9 (char 2324)\r\n\r\nDuring handling of the above exception, another exception occurred:\r\n\r\nTraceback (most recent call last):\r\n  File \"C:\\Users\\Hannes\\Documents\\GitHub\\Auto-GPT\\autogpt\\logs.py\", line 211, in print_assistant_thoughts\r\n    assistant_reply_json = fix_and_parse_json(assistant_reply)\r\n                           ^^^^^^^^^^^^^^^^^^^^^^^^^^^^^^^^^^^\r\n  File \"C:\\Users\\Hannes\\Documents\\GitHub\\Auto-GPT\\autogpt\\json_fixes\\parsing.py\", line 107, in fix_and_parse_json\r\n    return try_ai_fix(try_to_fix_with_gpt, e, json_to_load)\r\n           ^^^^^^^^^^^^^^^^^^^^^^^^^^^^^^^^^^^^^^^^^^^^^^^^\r\n  File \"C:\\Users\\Hannes\\Documents\\GitHub\\Auto-GPT\\autogpt\\json_fixes\\parsing.py\", line 136, in try_ai_fix\r\n    ai_fixed_json = fix_json(json_to_load, JSON_SCHEMA)\r\n                    ^^^^^^^^^^^^^^^^^^^^^^^^^^^^^^^^^^^\r\n  File \"C:\\Users\\Hannes\\Documents\\GitHub\\Auto-GPT\\autogpt\\json_fixes\\auto_fix.py\", line 24, in fix_json\r\n    function_string, args, description_string, model=cfg.fast_llm_model\r\n                                                     ^^^\r\nNameError: name 'cfg' is not defined`\n\n### Expected behavior \ud83e\udd14\n\nBefore the latest pull he didn't run into this error\n\n### Your prompt \ud83d\udcdd\n\n```yaml\r\n# \r\nai_goals:\r\n- 'Read {''file'': instructions.txt} and follow and follow any instructions in that\r\n  file'\r\n- 'Periodically read the file {''file'': instructions.txt} and follow any instructions\r\n  in that file'\r\n- 'Append your thinking process in tekst to the file {''file'': thinking.txt}'\r\nai_name: A\r\nai_role: An AI Designed to autonomously write, build, evaluate and improve code\r\n```\r\n", "reactions": {"url": "https://api.github.com/repos/Significant-Gravitas/Auto-GPT/issues/1614/reactions", "total_count": 0, "+1": 0, "-1": 0, "laugh": 0, "hooray": 0, "confused": 0, "heart": 0, "rocket": 0, "eyes": 0}, "timeline_url": "https://api.github.com/repos/Significant-Gravitas/Auto-GPT/issues/1614/timeline", "performed_via_github_app": null, "state_reason": null}