{"url": "https://api.github.com/repos/Significant-Gravitas/Auto-GPT/issues/3366", "repository_url": "https://api.github.com/repos/Significant-Gravitas/Auto-GPT", "labels_url": "https://api.github.com/repos/Significant-Gravitas/Auto-GPT/issues/3366/labels{/name}", "comments_url": "https://api.github.com/repos/Significant-Gravitas/Auto-GPT/issues/3366/comments", "events_url": "https://api.github.com/repos/Significant-Gravitas/Auto-GPT/issues/3366/events", "html_url": "https://github.com/Significant-Gravitas/Auto-GPT/issues/3366", "id": 1685881473, "node_id": "I_kwDOJKSTjM5kfIKB", "number": 3366, "title": "ISSUE WHEN REOPENING AUTOGPT ON MAC", "user": {"login": "xNicky2k", "id": 131925679, "node_id": "U_kgDOB90Grw", "avatar_url": "https://avatars.githubusercontent.com/u/131925679?v=4", "gravatar_id": "", "url": "https://api.github.com/users/xNicky2k", "html_url": "https://github.com/xNicky2k", "followers_url": "https://api.github.com/users/xNicky2k/followers", "following_url": "https://api.github.com/users/xNicky2k/following{/other_user}", "gists_url": "https://api.github.com/users/xNicky2k/gists{/gist_id}", "starred_url": "https://api.github.com/users/xNicky2k/starred{/owner}{/repo}", "subscriptions_url": "https://api.github.com/users/xNicky2k/subscriptions", "organizations_url": "https://api.github.com/users/xNicky2k/orgs", "repos_url": "https://api.github.com/users/xNicky2k/repos", "events_url": "https://api.github.com/users/xNicky2k/events{/privacy}", "received_events_url": "https://api.github.com/users/xNicky2k/received_events", "type": "User", "site_admin": false}, "labels": [{"id": 5347563882, "node_id": "LA_kwDOJKSTjM8AAAABPr1Zag", "url": "https://api.github.com/repos/Significant-Gravitas/Auto-GPT/labels/setup", "name": "setup", "color": "E1BC6F", "default": false, "description": "Issues with getting Auto-GPT setup on local machines"}], "state": "open", "locked": false, "assignee": null, "assignees": [], "milestone": null, "comments": 1, "created_at": "2023-04-26T23:45:48Z", "updated_at": "2023-04-27T09:06:37Z", "closed_at": null, "author_association": "NONE", "active_lock_reason": null, "body": "### \u26a0\ufe0f Search for existing issues first \u26a0\ufe0f\n\n- [X] I have searched the existing issues, and there is no existing issue for my problem\n\n### Which Operating System are you using?\n\nMacOS\n\n### Which version of Auto-GPT are you using?\n\nMaster (branch)\n\n### GPT-3 or GPT-4?\n\nGPT-3.5\n\n### Steps to reproduce \ud83d\udd79\n\n?\n\n### Current behavior \ud83d\ude2f\n\nauto gpt won't run \n\n### Expected behavior \ud83e\udd14\n\nauto gpt should run\n\n### Your prompt \ud83d\udcdd\n\n```yaml\r\ntraceback (most recent call last):\r\n  File \"<frozen runpy>\", line 189, in _run_module_as_main\r\n  File \"<frozen runpy>\", line 148, in _get_module_details\r\n  File \"<frozen runpy>\", line 112, in _get_module_details\r\n  File \"/Users/nickboutilier/Auto-GPT/autogpt/__init__.py\", line 1, in <module>\r\n    from dotenv import load_dotenv\r\nModuleNotFoundError: No module named 'dotenv'\r\n```\r\n\n\n### Your Logs \ud83d\udcd2\n\n```log\r\npermission denied\r\n```\r\n", "reactions": {"url": "https://api.github.com/repos/Significant-Gravitas/Auto-GPT/issues/3366/reactions", "total_count": 0, "+1": 0, "-1": 0, "laugh": 0, "hooray": 0, "confused": 0, "heart": 0, "rocket": 0, "eyes": 0}, "timeline_url": "https://api.github.com/repos/Significant-Gravitas/Auto-GPT/issues/3366/timeline", "performed_via_github_app": null, "state_reason": null}