{"url": "https://api.github.com/repos/Significant-Gravitas/Auto-GPT/issues/1161", "repository_url": "https://api.github.com/repos/Significant-Gravitas/Auto-GPT", "labels_url": "https://api.github.com/repos/Significant-Gravitas/Auto-GPT/issues/1161/labels{/name}", "comments_url": "https://api.github.com/repos/Significant-Gravitas/Auto-GPT/issues/1161/comments", "events_url": "https://api.github.com/repos/Significant-Gravitas/Auto-GPT/issues/1161/events", "html_url": "https://github.com/Significant-Gravitas/Auto-GPT/issues/1161", "id": 1666917535, "node_id": "I_kwDOJKSTjM5jWySf", "number": 1161, "title": "Deleted my pinecone index - main.py not checking if index exists before starting?", "user": {"login": "loseryoda", "id": 31484379, "node_id": "MDQ6VXNlcjMxNDg0Mzc5", "avatar_url": "https://avatars.githubusercontent.com/u/31484379?v=4", "gravatar_id": "", "url": "https://api.github.com/users/loseryoda", "html_url": "https://github.com/loseryoda", "followers_url": "https://api.github.com/users/loseryoda/followers", "following_url": "https://api.github.com/users/loseryoda/following{/other_user}", "gists_url": "https://api.github.com/users/loseryoda/gists{/gist_id}", "starred_url": "https://api.github.com/users/loseryoda/starred{/owner}{/repo}", "subscriptions_url": "https://api.github.com/users/loseryoda/subscriptions", "organizations_url": "https://api.github.com/users/loseryoda/orgs", "repos_url": "https://api.github.com/users/loseryoda/repos", "events_url": "https://api.github.com/users/loseryoda/events{/privacy}", "received_events_url": "https://api.github.com/users/loseryoda/received_events", "type": "User", "site_admin": false}, "labels": [{"id": 5272676243, "node_id": "LA_kwDOJKSTjM8AAAABOkankw", "url": "https://api.github.com/repos/Significant-Gravitas/Auto-GPT/labels/enhancement", "name": "enhancement", "color": "a2eeef", "default": true, "description": "New feature or request"}, {"id": 5409160395, "node_id": "LA_kwDOJKSTjM8AAAABQmk8yw", "url": "https://api.github.com/repos/Significant-Gravitas/Auto-GPT/labels/function:%20memory", "name": "function: memory", "color": "E12F75", "default": false, "description": ""}], "state": "open", "locked": false, "assignee": null, "assignees": [], "milestone": null, "comments": 2, "created_at": "2023-04-13T18:18:31Z", "updated_at": "2023-04-24T12:11:40Z", "closed_at": null, "author_association": "NONE", "active_lock_reason": null, "body": "### Duplicates\n\n- [X] I have searched the existing issues\n\n### Steps to reproduce \ud83d\udd79\n\n- start autogpt with  `MEMORY_BACKEND=pinecone`\r\n- delete pinecone index\r\n- restart autogpt and receive the following error:\r\n`Traceback (most recent call last):\r\n  File \"D:\\AI\\Auto-GPT\\Auto-GPT\\scripts\\main.py\", line 335, in <module>\r\n    memory = get_memory(cfg, init=True)\r\n             ^^^^^^^^^^^^^^^^^^^^^^^^^^\r\n  File \"D:\\AI\\Auto-GPT\\Auto-GPT\\scripts\\memory\\__init__.py\", line 30, in get_memory\r\n    memory.clear()\r\n  File \"D:\\AI\\Auto-GPT\\Auto-GPT\\scripts\\memory\\pinecone.py\", line 36, in clear\r\n    self.index.delete(deleteAll=True)\r\n  File \"C:\\Users\\PC\\AppData\\Local\\Programs\\Python\\Python311\\Lib\\site-packages\\pinecone\\core\\utils\\error_handling.py\", line 17, in inner_func\r\n    return func(*args, **kwargs)\r\n           ^^^^^^^^^^^^^^^^^^^^^\r\n  File \"C:\\Users\\PC\\AppData\\Local\\Programs\\Python\\Python311\\Lib\\site-packages\\pinecone\\index.py\", line 329, in delete\r\n    return self._vector_api.delete(\r\n           ^^^^^^^^^^^^^^^^^^^^^^^^\r\n  File \"C:\\Users\\PC\\AppData\\Local\\Programs\\Python\\Python311\\Lib\\site-packages\\pinecone\\core\\client\\api_client.py\", line 776, in __call__\r\n    return self.callable(self, *args, **kwargs)\r\n           ^^^^^^^^^^^^^^^^^^^^^^^^^^^^^^^^^^^^\r\n  File \"C:\\Users\\PC\\AppData\\Local\\Programs\\Python\\Python311\\Lib\\site-packages\\pinecone\\core\\client\\api\\vector_operations_api.py\", line 117, in __delete\r\n    return self.call_with_http_info(**kwargs)\r\n           ^^^^^^^^^^^^^^^^^^^^^^^^^^^^^^^^^^\r\n  File \"C:\\Users\\PC\\AppData\\Local\\Programs\\Python\\Python311\\Lib\\site-packages\\pinecone\\core\\client\\api_client.py\", line 838, in call_with_http_info\r\n    return self.api_client.call_api(\r\n           ^^^^^^^^^^^^^^^^^^^^^^^^^\r\n  File \"C:\\Users\\PC\\AppData\\Local\\Programs\\Python\\Python311\\Lib\\site-packages\\pinecone\\core\\client\\api_client.py\", line 413, in call_api\r\n    return self.__call_api(resource_path, method,\r\n           ^^^^^^^^^^^^^^^^^^^^^^^^^^^^^^^^^^^^^^\r\n  File \"C:\\Users\\PC\\AppData\\Local\\Programs\\Python\\Python311\\Lib\\site-packages\\pinecone\\core\\client\\api_client.py\", line 207, in __call_api\r\n    raise e\r\n  File \"C:\\Users\\PC\\AppData\\Local\\Programs\\Python\\Python311\\Lib\\site-packages\\pinecone\\core\\client\\api_client.py\", line 200, in __call_api\r\n    response_data = self.request(\r\n                    ^^^^^^^^^^^^^\r\n  File \"C:\\Users\\PC\\AppData\\Local\\Programs\\Python\\Python311\\Lib\\site-packages\\pinecone\\core\\client\\api_client.py\", line 459, in request\r\n    return self.rest_client.POST(url,\r\n           ^^^^^^^^^^^^^^^^^^^^^^^^^^\r\n  File \"C:\\Users\\PC\\AppData\\Local\\Programs\\Python\\Python311\\Lib\\site-packages\\pinecone\\core\\client\\rest.py\", line 271, in POST\r\n    return self.request(\"POST\", url,\r\n           ^^^^^^^^^^^^^^^^^^^^^^^^^\r\n  File \"C:\\Users\\PC\\AppData\\Local\\Programs\\Python\\Python311\\Lib\\site-packages\\pinecone\\core\\client\\rest.py\", line 222, in request\r\n    raise ForbiddenException(http_resp=r)\r\npinecone.core.client.exceptions.ForbiddenException: (403)\r\nReason: Forbidden\r\nHTTP response headers: HTTPHeaderDict({'content-length': '0', 'date': 'Thu, 13 Apr 2023 18:12:17 GMT', 'server': 'envoy'})`\n\n### Current behavior \ud83d\ude2f\n\n- not starting\r\n- having either to manually recreate index or modifying code\n\n### Expected behavior \ud83e\udd14\n\n- just create a new index\n\n### Your prompt \ud83d\udcdd\n\nnot relevant", "reactions": {"url": "https://api.github.com/repos/Significant-Gravitas/Auto-GPT/issues/1161/reactions", "total_count": 0, "+1": 0, "-1": 0, "laugh": 0, "hooray": 0, "confused": 0, "heart": 0, "rocket": 0, "eyes": 0}, "timeline_url": "https://api.github.com/repos/Significant-Gravitas/Auto-GPT/issues/1161/timeline", "performed_via_github_app": null, "state_reason": null}