{"url": "https://api.github.com/repos/Significant-Gravitas/Auto-GPT/issues/3614", "repository_url": "https://api.github.com/repos/Significant-Gravitas/Auto-GPT", "labels_url": "https://api.github.com/repos/Significant-Gravitas/Auto-GPT/issues/3614/labels{/name}", "comments_url": "https://api.github.com/repos/Significant-Gravitas/Auto-GPT/issues/3614/comments", "events_url": "https://api.github.com/repos/Significant-Gravitas/Auto-GPT/issues/3614/events", "html_url": "https://github.com/Significant-Gravitas/Auto-GPT/issues/3614", "id": 1690549953, "node_id": "I_kwDOJKSTjM5kw77B", "number": 3614, "title": "window run: .\\run.bat  error ", "user": {"login": "lishiyi1111", "id": 103713122, "node_id": "U_kgDOBi6JYg", "avatar_url": "https://avatars.githubusercontent.com/u/103713122?v=4", "gravatar_id": "", "url": "https://api.github.com/users/lishiyi1111", "html_url": "https://github.com/lishiyi1111", "followers_url": "https://api.github.com/users/lishiyi1111/followers", "following_url": "https://api.github.com/users/lishiyi1111/following{/other_user}", "gists_url": "https://api.github.com/users/lishiyi1111/gists{/gist_id}", "starred_url": "https://api.github.com/users/lishiyi1111/starred{/owner}{/repo}", "subscriptions_url": "https://api.github.com/users/lishiyi1111/subscriptions", "organizations_url": "https://api.github.com/users/lishiyi1111/orgs", "repos_url": "https://api.github.com/users/lishiyi1111/repos", "events_url": "https://api.github.com/users/lishiyi1111/events{/privacy}", "received_events_url": "https://api.github.com/users/lishiyi1111/received_events", "type": "User", "site_admin": false}, "labels": [{"id": 5347563882, "node_id": "LA_kwDOJKSTjM8AAAABPr1Zag", "url": "https://api.github.com/repos/Significant-Gravitas/Auto-GPT/labels/setup", "name": "setup", "color": "E1BC6F", "default": false, "description": "Issues with getting Auto-GPT setup on local machines"}], "state": "open", "locked": false, "assignee": null, "assignees": [], "milestone": null, "comments": 2, "created_at": "2023-05-01T08:20:51Z", "updated_at": "2023-05-02T02:43:10Z", "closed_at": null, "author_association": "NONE", "active_lock_reason": null, "body": "### \u26a0\ufe0f Search for existing issues first \u26a0\ufe0f\n\n- [X] I have searched the existing issues, and there is no existing issue for my problem\n\n### Which Operating System are you using?\n\nWindows\n\n### Which version of Auto-GPT are you using?\n\nStable (branch)\n\n### GPT-3 or GPT-4?\n\nGPT-3.5\n\n### Steps to reproduce \ud83d\udd79\n\ns/download/en_core_web_sm-3.4.0/en_core_web_sm-3.4.0-py3-none-any.whl\r\n  WARNING: Retrying (Retry(total=0, connect=None, read=None, redirect=None, status=None)) after connection broken by 'SSLError(SSLZeroReturnError(6, 'TLS/SSL connection has been closed (EOF) (_ssl.c:1131)'))': /explosion/spacy-models/releases/download/en_core_web_sm-3.4.0/en_core_web_sm-3.4.0-py3-none-any.whl\r\nERROR: Could not install packages due to an OSError: HTTPSConnectionPool(host='github.com', port=443): Max retries exceeded with url: /explosion/spacy-models/releases/download/en_core_web_sm-3.4.0/en_core_web_sm-3.4.0-py3-none-any.whl (Caused by SSLError(SSLZeroReturnError(6, 'TLS/SSL connection has been closed (EOF) (_ssl.c:1131)')))\r\n\r\nCould not fetch URL https://pypi.org/simple/pip/: There was a problem confirming the ssl certificate: HTTPSConnectionPool(host='pypi.org', port=443): Max retries exceeded with url: /simple/pip/ (Caused by SSLError(SSLZeroReturnError(6, 'TLS/SSL connection has been closed (EOF) (_ssl.c:1131)'))) - skipping\r\nTraceback (most recent call last):\r\n  File \"D:\\Anaconda\\envs\\auto-gpt\\lib\\runpy.py\", line 194, in _run_module_as_main\r\n    return _run_code(code, main_globals, None,\r\n  File \"D:\\Anaconda\\envs\\auto-gpt\\lib\\runpy.py\", line 87, in _run_code\r\n    exec(code, run_globals)\r\n  File \"D:\\Auto-GPT\\Auto-GPT-stable-0.2.2\\autogpt\\__main__.py\", line 2, in <module>\r\n    import autogpt.cli\r\n  File \"D:\\Auto-GPT\\Auto-GPT-stable-0.2.2\\autogpt\\cli.py\", line 2, in <module>\r\n    import click\r\nModuleNotFoundError: No module named 'click'\r\n\u8bf7\u6309\u4efb\u610f\u952e\u7ee7\u7eed. . .\n\n### Current behavior \ud83d\ude2f\n\ns/download/en_core_web_sm-3.4.0/en_core_web_sm-3.4.0-py3-none-any.whl\r\n  WARNING: Retrying (Retry(total=0, connect=None, read=None, redirect=None, status=None)) after connection broken by 'SSLError(SSLZeroReturnError(6, 'TLS/SSL connection has been closed (EOF) (_ssl.c:1131)'))': /explosion/spacy-models/releases/download/en_core_web_sm-3.4.0/en_core_web_sm-3.4.0-py3-none-any.whl\r\nERROR: Could not install packages due to an OSError: HTTPSConnectionPool(host='github.com', port=443): Max retries exceeded with url: /explosion/spacy-models/releases/download/en_core_web_sm-3.4.0/en_core_web_sm-3.4.0-py3-none-any.whl (Caused by SSLError(SSLZeroReturnError(6, 'TLS/SSL connection has been closed (EOF) (_ssl.c:1131)')))\r\n\r\nCould not fetch URL https://pypi.org/simple/pip/: There was a problem confirming the ssl certificate: HTTPSConnectionPool(host='pypi.org', port=443): Max retries exceeded with url: /simple/pip/ (Caused by SSLError(SSLZeroReturnError(6, 'TLS/SSL connection has been closed (EOF) (_ssl.c:1131)'))) - skipping\r\nTraceback (most recent call last):\r\n  File \"D:\\Anaconda\\envs\\auto-gpt\\lib\\runpy.py\", line 194, in _run_module_as_main\r\n    return _run_code(code, main_globals, None,\r\n  File \"D:\\Anaconda\\envs\\auto-gpt\\lib\\runpy.py\", line 87, in _run_code\r\n    exec(code, run_globals)\r\n  File \"D:\\Auto-GPT\\Auto-GPT-stable-0.2.2\\autogpt\\__main__.py\", line 2, in <module>\r\n    import autogpt.cli\r\n  File \"D:\\Auto-GPT\\Auto-GPT-stable-0.2.2\\autogpt\\cli.py\", line 2, in <module>\r\n    import click\r\nModuleNotFoundError: No module named 'click'\r\n\u8bf7\u6309\u4efb\u610f\u952e\u7ee7\u7eed. . .\n\n### Expected behavior \ud83e\udd14\n\nshould download something\n\n### Your prompt \ud83d\udcdd\n\n```yaml\r\n# Paste your prompt here\r\n```\r\n\n\n### Your Logs \ud83d\udcd2\n\n```log\r\n<insert your logs here>\r\n```\r\n", "reactions": {"url": "https://api.github.com/repos/Significant-Gravitas/Auto-GPT/issues/3614/reactions", "total_count": 0, "+1": 0, "-1": 0, "laugh": 0, "hooray": 0, "confused": 0, "heart": 0, "rocket": 0, "eyes": 0}, "timeline_url": "https://api.github.com/repos/Significant-Gravitas/Auto-GPT/issues/3614/timeline", "performed_via_github_app": null, "state_reason": null}