{"url": "https://api.github.com/repos/Significant-Gravitas/Auto-GPT/issues/2684", "repository_url": "https://api.github.com/repos/Significant-Gravitas/Auto-GPT", "labels_url": "https://api.github.com/repos/Significant-Gravitas/Auto-GPT/issues/2684/labels{/name}", "comments_url": "https://api.github.com/repos/Significant-Gravitas/Auto-GPT/issues/2684/comments", "events_url": "https://api.github.com/repos/Significant-Gravitas/Auto-GPT/issues/2684/events", "html_url": "https://github.com/Significant-Gravitas/Auto-GPT/issues/2684", "id": 1676927586, "node_id": "I_kwDOJKSTjM5j8-Ji", "number": 2684, "title": "Error: The model: `gpt-4` does not exist", "user": {"login": "LPanic", "id": 62666957, "node_id": "MDQ6VXNlcjYyNjY2OTU3", "avatar_url": "https://avatars.githubusercontent.com/u/62666957?v=4", "gravatar_id": "", "url": "https://api.github.com/users/LPanic", "html_url": "https://github.com/LPanic", "followers_url": "https://api.github.com/users/LPanic/followers", "following_url": "https://api.github.com/users/LPanic/following{/other_user}", "gists_url": "https://api.github.com/users/LPanic/gists{/gist_id}", "starred_url": "https://api.github.com/users/LPanic/starred{/owner}{/repo}", "subscriptions_url": "https://api.github.com/users/LPanic/subscriptions", "organizations_url": "https://api.github.com/users/LPanic/orgs", "repos_url": "https://api.github.com/users/LPanic/repos", "events_url": "https://api.github.com/users/LPanic/events{/privacy}", "received_events_url": "https://api.github.com/users/LPanic/received_events", "type": "User", "site_admin": false}, "labels": [{"id": 5272676193, "node_id": "LA_kwDOJKSTjM8AAAABOkanYQ", "url": "https://api.github.com/repos/Significant-Gravitas/Auto-GPT/labels/bug", "name": "bug", "color": "d73a4a", "default": true, "description": "Something isn't working"}, {"id": 5337009318, "node_id": "LA_kwDOJKSTjM8AAAABPhxMpg", "url": "https://api.github.com/repos/Significant-Gravitas/Auto-GPT/labels/high%20priority", "name": "high priority", "color": "D93F0B", "default": false, "description": ""}, {"id": 5401552627, "node_id": "LA_kwDOJKSTjM8AAAABQfUm8w", "url": "https://api.github.com/repos/Significant-Gravitas/Auto-GPT/labels/needs%20investigation", "name": "needs investigation", "color": "C3708F", "default": false, "description": ""}], "state": "open", "locked": false, "assignee": null, "assignees": [], "milestone": null, "comments": 15, "created_at": "2023-04-20T15:11:44Z", "updated_at": "2023-04-28T05:07:47Z", "closed_at": null, "author_association": "NONE", "active_lock_reason": null, "body": "### Discussed in https://github.com/Significant-Gravitas/Auto-GPT/discussions/423\r\n\r\nI ran it with the **--gpt4only** parameter\r\nopenai.error.InvalidRequestError: The model: `**gpt-4**` does not exist. Although active GPT4 subscription and not at API-limit\r\n\r\n![alt text](https://s20.directupload.net/images/230420/nd7cxa9l.png)\r\n\r\n```\r\nTraceback (most recent call last):\r\n  File \"<frozen runpy>\", line 198, in _run_module_as_main\r\n  File \"<frozen runpy>\", line 88, in _run_code\r\n  File \"C:\\Users\\marti\\AI\\Auto-GPT\\autogpt\\__main__.py\", line 5, in <module>\r\n    autogpt.cli.main()\r\n  File \"C:\\Users\\marti\\AppData\\Local\\Programs\\Python\\Python311\\Lib\\site-packages\\click\\core.py\", line 1130, in __call__\r\n    return self.main(*args, **kwargs)\r\n           ^^^^^^^^^^^^^^^^^^^^^^^^^^\r\n  File \"C:\\Users\\marti\\AppData\\Local\\Programs\\Python\\Python311\\Lib\\site-packages\\click\\core.py\", line 1055, in main\r\n    rv = self.invoke(ctx)\r\n         ^^^^^^^^^^^^^^^^\r\n  File \"C:\\Users\\marti\\AppData\\Local\\Programs\\Python\\Python311\\Lib\\site-packages\\click\\core.py\", line 1635, in invoke\r\n    rv = super().invoke(ctx)\r\n         ^^^^^^^^^^^^^^^^^^^\r\n  File \"C:\\Users\\marti\\AppData\\Local\\Programs\\Python\\Python311\\Lib\\site-packages\\click\\core.py\", line 1404, in invoke\r\n    return ctx.invoke(self.callback, **ctx.params)\r\n           ^^^^^^^^^^^^^^^^^^^^^^^^^^^^^^^^^^^^^^^\r\n  File \"C:\\Users\\marti\\AppData\\Local\\Programs\\Python\\Python311\\Lib\\site-packages\\click\\core.py\", line 760, in invoke\r\n    return __callback(*args, **kwargs)\r\n           ^^^^^^^^^^^^^^^^^^^^^^^^^^^\r\n  File \"C:\\Users\\marti\\AppData\\Local\\Programs\\Python\\Python311\\Lib\\site-packages\\click\\decorators.py\", line 26, in new_func\r\n    return f(get_current_context(), *args, **kwargs)\r\n           ^^^^^^^^^^^^^^^^^^^^^^^^^^^^^^^^^^^^^^^^^\r\n  File \"C:\\Users\\marti\\AI\\Auto-GPT\\autogpt\\cli.py\", line 151, in main\r\n    agent.start_interaction_loop()\r\n  File \"C:\\Users\\marti\\AI\\Auto-GPT\\autogpt\\agent\\agent.py\", line 75, in start_interaction_loop\r\n    assistant_reply = chat_with_ai(\r\n                      ^^^^^^^^^^^^^\r\n  File \"C:\\Users\\marti\\AI\\Auto-GPT\\autogpt\\chat.py\", line 159, in chat_with_ai\r\n    assistant_reply = create_chat_completion(\r\n                      ^^^^^^^^^^^^^^^^^^^^^^^\r\n  File \"C:\\Users\\marti\\AI\\Auto-GPT\\autogpt\\llm_utils.py\", line 93, in create_chat_completion\r\n    response = openai.ChatCompletion.create(\r\n               ^^^^^^^^^^^^^^^^^^^^^^^^^^^^^\r\n  File \"C:\\Users\\marti\\AppData\\Local\\Programs\\Python\\Python311\\Lib\\site-packages\\openai\\api_resources\\chat_completion.py\", line 25, in create\r\n    return super().create(*args, **kwargs)\r\n           ^^^^^^^^^^^^^^^^^^^^^^^^^^^^^^^\r\n  File \"C:\\Users\\marti\\AppData\\Local\\Programs\\Python\\Python311\\Lib\\site-packages\\openai\\api_resources\\abstract\\engine_api_resource.py\", line 153, in create\r\n    response, _, api_key = requestor.request(\r\n                           ^^^^^^^^^^^^^^^^^^\r\n  File \"C:\\Users\\marti\\AppData\\Local\\Programs\\Python\\Python311\\Lib\\site-packages\\openai\\api_requestor.py\", line 226, in request\r\n    resp, got_stream = self._interpret_response(result, stream)\r\n                       ^^^^^^^^^^^^^^^^^^^^^^^^^^^^^^^^^^^^^^^^\r\n  File \"C:\\Users\\marti\\AppData\\Local\\Programs\\Python\\Python311\\Lib\\site-packages\\openai\\api_requestor.py\", line 619, in _interpret_response\r\n    self._interpret_response_line(\r\n  File \"C:\\Users\\marti\\AppData\\Local\\Programs\\Python\\Python311\\Lib\\site-packages\\openai\\api_requestor.py\", line 682, in _interpret_response_line\r\n    raise self.handle_error_response(\r\nopenai.error.InvalidRequestError: The model: `gpt-4` does not exist\r\n```", "reactions": {"url": "https://api.github.com/repos/Significant-Gravitas/Auto-GPT/issues/2684/reactions", "total_count": 5, "+1": 0, "-1": 0, "laugh": 0, "hooray": 0, "confused": 0, "heart": 5, "rocket": 0, "eyes": 0}, "timeline_url": "https://api.github.com/repos/Significant-Gravitas/Auto-GPT/issues/2684/timeline", "performed_via_github_app": null, "state_reason": null}