{"url": "https://api.github.com/repos/Significant-Gravitas/Auto-GPT/issues/2773", "repository_url": "https://api.github.com/repos/Significant-Gravitas/Auto-GPT", "labels_url": "https://api.github.com/repos/Significant-Gravitas/Auto-GPT/issues/2773/labels{/name}", "comments_url": "https://api.github.com/repos/Significant-Gravitas/Auto-GPT/issues/2773/comments", "events_url": "https://api.github.com/repos/Significant-Gravitas/Auto-GPT/issues/2773/events", "html_url": "https://github.com/Significant-Gravitas/Auto-GPT/issues/2773", "id": 1677857694, "node_id": "I_kwDOJKSTjM5kAhOe", "number": 2773, "title": "ImportError: DLL load failed while importing numpy_ops: The specified module could not be found", "user": {"login": "intuitiveit-dev", "id": 117691090, "node_id": "U_kgDOBwPS0g", "avatar_url": "https://avatars.githubusercontent.com/u/117691090?v=4", "gravatar_id": "", "url": "https://api.github.com/users/intuitiveit-dev", "html_url": "https://github.com/intuitiveit-dev", "followers_url": "https://api.github.com/users/intuitiveit-dev/followers", "following_url": "https://api.github.com/users/intuitiveit-dev/following{/other_user}", "gists_url": "https://api.github.com/users/intuitiveit-dev/gists{/gist_id}", "starred_url": "https://api.github.com/users/intuitiveit-dev/starred{/owner}{/repo}", "subscriptions_url": "https://api.github.com/users/intuitiveit-dev/subscriptions", "organizations_url": "https://api.github.com/users/intuitiveit-dev/orgs", "repos_url": "https://api.github.com/users/intuitiveit-dev/repos", "events_url": "https://api.github.com/users/intuitiveit-dev/events{/privacy}", "received_events_url": "https://api.github.com/users/intuitiveit-dev/received_events", "type": "User", "site_admin": false}, "labels": [{"id": 5272676193, "node_id": "LA_kwDOJKSTjM8AAAABOkanYQ", "url": "https://api.github.com/repos/Significant-Gravitas/Auto-GPT/labels/bug", "name": "bug", "color": "d73a4a", "default": true, "description": "Something isn't working"}, {"id": 5272676214, "node_id": "LA_kwDOJKSTjM8AAAABOkandg", "url": "https://api.github.com/repos/Significant-Gravitas/Auto-GPT/labels/documentation", "name": "documentation", "color": "0075ca", "default": true, "description": "Improvements or additions to documentation"}, {"id": 5421480443, "node_id": "LA_kwDOJKSTjM8AAAABQyU5-w", "url": "https://api.github.com/repos/Significant-Gravitas/Auto-GPT/labels/Windows", "name": "Windows", "color": "5319E7", "default": false, "description": ""}], "state": "open", "locked": false, "assignee": null, "assignees": [], "milestone": null, "comments": 9, "created_at": "2023-04-21T05:49:41Z", "updated_at": "2023-04-30T21:40:34Z", "closed_at": null, "author_association": "NONE", "active_lock_reason": null, "body": "Hi Everyone,\r\n\r\nI am getting this error after installing Auto-GPT 0.2.2 on a fresh install of Windows 10 with Python310\r\n\r\n**Environment**\r\nThis is running in a VirtualBox VM setup just for AutoGPT so the environment is only set up according to the Auto-GPT install directions\r\nAuto-GPT 0.2.2\r\nWindows 10\r\nPython310\r\n\r\n**Steps to reproduce**\r\nInstall Python 3\r\nDownload Auto-GPT 0.2.2\r\npip install -r requirements.txt\r\n\r\n**Full stack trace:**\r\nC:\\Auto-GPT-0.2.2>python -m autogpt\r\nWarning: The file 'auto-gpt.json' does not exist. Local memory would not be saved to a file.\r\nTraceback (most recent call last):\r\n  File \"C:\\Users\\AutoGPT\\AppData\\Local\\Programs\\Python\\Python310\\lib\\runpy.py\", line 196, in _run_module_as_main\r\n    return _run_code(code, main_globals, None,\r\n  File \"C:\\Users\\AutoGPT\\AppData\\Local\\Programs\\Python\\Python310\\lib\\runpy.py\", line 86, in _run_code\r\n    exec(code, run_globals)\r\n  File \"C:\\Auto-GPT-0.2.2\\autogpt\\__main__.py\", line 5, in <module>\r\n    autogpt.cli.main()\r\n  File \"C:\\Users\\AutoGPT\\AppData\\Local\\Programs\\Python\\Python310\\lib\\site-packages\\click\\core.py\", line 1130, in __call__\r\n    return self.main(*args, **kwargs)\r\n  File \"C:\\Users\\AutoGPT\\AppData\\Local\\Programs\\Python\\Python310\\lib\\site-packages\\click\\core.py\", line 1055, in main\r\n    rv = self.invoke(ctx)\r\n  File \"C:\\Users\\AutoGPT\\AppData\\Local\\Programs\\Python\\Python310\\lib\\site-packages\\click\\core.py\", line 1635, in invoke\r\n    rv = super().invoke(ctx)\r\n  File \"C:\\Users\\AutoGPT\\AppData\\Local\\Programs\\Python\\Python310\\lib\\site-packages\\click\\core.py\", line 1404, in invoke\r\n    return ctx.invoke(self.callback, **ctx.params)\r\n  File \"C:\\Users\\AutoGPT\\AppData\\Local\\Programs\\Python\\Python310\\lib\\site-packages\\click\\core.py\", line 760, in invoke\r\n    return __callback(*args, **kwargs)\r\n  File \"C:\\Users\\AutoGPT\\AppData\\Local\\Programs\\Python\\Python310\\lib\\site-packages\\click\\decorators.py\", line 26, in new_func\r\n    return f(get_current_context(), *args, **kwargs)\r\n  File \"C:\\Auto-GPT-0.2.2\\autogpt\\cli.py\", line 77, in main\r\n    from autogpt.agent.agent import Agent\r\n  File \"C:\\Auto-GPT-0.2.2\\autogpt\\agent\\__init__.py\", line 1, in <module>\r\n    from autogpt.agent.agent import Agent\r\n  File \"C:\\Auto-GPT-0.2.2\\autogpt\\agent\\agent.py\", line 3, in <module>\r\n    from autogpt.app import execute_command, get_command\r\n  File \"C:\\Auto-GPT-0.2.2\\autogpt\\app.py\", line 27, in <module>\r\n    from autogpt.commands.web_selenium import browse_website\r\n  File \"C:\\Auto-GPT-0.2.2\\autogpt\\commands\\web_selenium.py\", line 20, in <module>\r\n    import autogpt.processing.text as summary\r\n  File \"C:\\Auto-GPT-0.2.2\\autogpt\\processing\\text.py\", line 4, in <module>\r\n    import spacy\r\n  File \"C:\\Users\\AutoGPT\\AppData\\Local\\Programs\\Python\\Python310\\lib\\site-packages\\spacy\\__init__.py\", line 6, in <module>\r\n    from .errors import setup_default_warnings\r\n  File \"C:\\Users\\AutoGPT\\AppData\\Local\\Programs\\Python\\Python310\\lib\\site-packages\\spacy\\errors.py\", line 2, in <module>\r\n    from .compat import Literal\r\n  File \"C:\\Users\\AutoGPT\\AppData\\Local\\Programs\\Python\\Python310\\lib\\site-packages\\spacy\\compat.py\", line 38, in <module>\r\n    from thinc.api import Optimizer  # noqa: F401\r\n  File \"C:\\Users\\AutoGPT\\AppData\\Local\\Programs\\Python\\Python310\\lib\\site-packages\\thinc\\api.py\", line 2, in <module>\r\n    from .initializers import normal_init, uniform_init, glorot_uniform_init, zero_init\r\n  File \"C:\\Users\\AutoGPT\\AppData\\Local\\Programs\\Python\\Python310\\lib\\site-packages\\thinc\\initializers.py\", line 4, in <module>\r\n    from .backends import Ops\r\n  File \"C:\\Users\\AutoGPT\\AppData\\Local\\Programs\\Python\\Python310\\lib\\site-packages\\thinc\\backends\\__init__.py\", line 8, in <module>\r\n    from .cupy_ops import CupyOps\r\n  File \"C:\\Users\\AutoGPT\\AppData\\Local\\Programs\\Python\\Python310\\lib\\site-packages\\thinc\\backends\\cupy_ops.py\", line 4, in <module>\r\n    from .numpy_ops import NumpyOps\r\nImportError: DLL load failed while importing numpy_ops: The specified module could not be found\r\n\r\n**What I have tried to fix it**\r\nThe numpy package installed is 1.24.2 and I have tried rolling this back to previous versions 1.14.6 for example\r\nI have also tried the master branch of Auto-GPT and get the same error\r\nI have tried reinstalling all requirements using pip install -r requirements.txt --force-reinstall\r\nAnd variously uninstalled and reinstalled numpy and spacy\r\n\r\n**Footnotes**\r\nLove the project. New to Python. Any help is appreciated!", "reactions": {"url": "https://api.github.com/repos/Significant-Gravitas/Auto-GPT/issues/2773/reactions", "total_count": 2, "+1": 2, "-1": 0, "laugh": 0, "hooray": 0, "confused": 0, "heart": 0, "rocket": 0, "eyes": 0}, "timeline_url": "https://api.github.com/repos/Significant-Gravitas/Auto-GPT/issues/2773/timeline", "performed_via_github_app": null, "state_reason": null}