{"url": "https://api.github.com/repos/Significant-Gravitas/Auto-GPT/issues/2874", "repository_url": "https://api.github.com/repos/Significant-Gravitas/Auto-GPT", "labels_url": "https://api.github.com/repos/Significant-Gravitas/Auto-GPT/issues/2874/labels{/name}", "comments_url": "https://api.github.com/repos/Significant-Gravitas/Auto-GPT/issues/2874/comments", "events_url": "https://api.github.com/repos/Significant-Gravitas/Auto-GPT/issues/2874/events", "html_url": "https://github.com/Significant-Gravitas/Auto-GPT/issues/2874", "id": 1679337896, "node_id": "I_kwDOJKSTjM5kGKmo", "number": 2874, "title": "Error Installing on Raspberry Pi OS", "user": {"login": "FuzzTalkAI", "id": 131419943, "node_id": "U_kgDOB9VPJw", "avatar_url": "https://avatars.githubusercontent.com/u/131419943?v=4", "gravatar_id": "", "url": "https://api.github.com/users/FuzzTalkAI", "html_url": "https://github.com/FuzzTalkAI", "followers_url": "https://api.github.com/users/FuzzTalkAI/followers", "following_url": "https://api.github.com/users/FuzzTalkAI/following{/other_user}", "gists_url": "https://api.github.com/users/FuzzTalkAI/gists{/gist_id}", "starred_url": "https://api.github.com/users/FuzzTalkAI/starred{/owner}{/repo}", "subscriptions_url": "https://api.github.com/users/FuzzTalkAI/subscriptions", "organizations_url": "https://api.github.com/users/FuzzTalkAI/orgs", "repos_url": "https://api.github.com/users/FuzzTalkAI/repos", "events_url": "https://api.github.com/users/FuzzTalkAI/events{/privacy}", "received_events_url": "https://api.github.com/users/FuzzTalkAI/received_events", "type": "User", "site_admin": false}, "labels": [{"id": 5272676214, "node_id": "LA_kwDOJKSTjM8AAAABOkandg", "url": "https://api.github.com/repos/Significant-Gravitas/Auto-GPT/labels/documentation", "name": "documentation", "color": "0075ca", "default": true, "description": "Improvements or additions to documentation"}, {"id": 5421459020, "node_id": "LA_kwDOJKSTjM8AAAABQyTmTA", "url": "https://api.github.com/repos/Significant-Gravitas/Auto-GPT/labels/Linux", "name": "Linux", "color": "5319E7", "default": false, "description": ""}], "state": "open", "locked": false, "assignee": null, "assignees": [], "milestone": null, "comments": 6, "created_at": "2023-04-22T05:03:03Z", "updated_at": "2023-05-02T06:37:34Z", "closed_at": null, "author_association": "NONE", "active_lock_reason": null, "body": "### \u26a0\ufe0f Search for existing issues first \u26a0\ufe0f\n\n- [X] I have searched the existing issues, and there is no existing issue for my problem\n\n### Which Operating System are you using?\n\nLinux\n\n### Which version of Auto-GPT are you using?\n\nLatest Release\n\n### GPT-3 or GPT-4?\n\nGPT-3.5\n\n### Steps to reproduce \ud83d\udd79\n\nI'm trying to install on the Raspberry Pi OS and everything seems to install correctly until I get to the prompt of ./run.sh it gives me this error\r\n\r\nHow do I fix this?\n\n### Current behavior \ud83d\ude2f\n\nJust throws the error\n\n### Expected behavior \ud83e\udd14\n\nIt should run Auto-GPT\n\n### Your prompt \ud83d\udcdd\n\n```yaml\r\n# Paste your prompt here\r\n```\r\nWarning: The file 'auto-gpt.json' does not exist. Local memory would not be saved to a file.\r\nTraceback (most recent call last):\r\n  File \"/usr/lib/python3.9/runpy.py\", line 197, in _run_module_as_main\r\n    return _run_code(code, main_globals, None,\r\n  File \"/usr/lib/python3.9/runpy.py\", line 87, in _run_code\r\n    exec(code, run_globals)\r\n  File \"/home/fuzzy427/Auto-GPT/autogpt/__main__.py\", line 5, in <module>\r\n    autogpt.cli.main()\r\n  File \"/usr/local/lib/python3.9/dist-packages/click/core.py\", line 1130, in __call__\r\n    return self.main(*args, **kwargs)\r\n  File \"/usr/local/lib/python3.9/dist-packages/click/core.py\", line 1055, in main\r\n    rv = self.invoke(ctx)\r\n  File \"/usr/local/lib/python3.9/dist-packages/click/core.py\", line 1635, in invoke\r\n    rv = super().invoke(ctx)\r\n  File \"/usr/local/lib/python3.9/dist-packages/click/core.py\", line 1404, in invoke\r\n    return ctx.invoke(self.callback, **ctx.params)\r\n  File \"/usr/local/lib/python3.9/dist-packages/click/core.py\", line 760, in invoke\r\n    return __callback(*args, **kwargs)\r\n  File \"/usr/local/lib/python3.9/dist-packages/click/decorators.py\", line 26, in new_func\r\n    return f(get_current_context(), *args, **kwargs)\r\n  File \"/home/fuzzy427/Auto-GPT/autogpt/cli.py\", line 77, in main\r\n    from autogpt.agent.agent import Agent\r\n  File \"/home/fuzzy427/Auto-GPT/autogpt/agent/__init__.py\", line 1, in <module>\r\n    from autogpt.agent.agent import Agent\r\n  File \"/home/fuzzy427/Auto-GPT/autogpt/agent/agent.py\", line 3, in <module>\r\n    from autogpt.app import execute_command, get_command\r\n  File \"/home/fuzzy427/Auto-GPT/autogpt/app.py\", line 27, in <module>\r\n    from autogpt.commands.web_selenium import browse_website\r\n  File \"/home/fuzzy427/Auto-GPT/autogpt/commands/web_selenium.py\", line 20, in <module>\r\n    import autogpt.processing.text as summary\r\n  File \"/home/fuzzy427/Auto-GPT/autogpt/processing/text.py\", line 4, in <module>\r\n    import spacy\r\n  File \"/home/fuzzy427/.local/lib/python3.9/site-packages/spacy/__init__.py\", line 6, in <module>\r\n    from .errors import setup_default_warnings\r\n  File \"/home/fuzzy427/.local/lib/python3.9/site-packages/spacy/errors.py\", line 2, in <module>\r\n    from .compat import Literal\r\n  File \"/home/fuzzy427/.local/lib/python3.9/site-packages/spacy/compat.py\", line 38, in <module>\r\n    from thinc.api import Optimizer  # noqa: F401\r\n  File \"/usr/local/lib/python3.9/dist-packages/thinc/api.py\", line 2, in <module>\r\n    from .initializers import normal_init, uniform_init, glorot_uniform_init, zero_init\r\n  File \"/usr/local/lib/python3.9/dist-packages/thinc/initializers.py\", line 4, in <module>\r\n    from .backends import Ops\r\n  File \"/usr/local/lib/python3.9/dist-packages/thinc/backends/__init__.py\", line 7, in <module>\r\n    from .ops import Ops\r\n  File \"/usr/local/lib/python3.9/dist-packages/thinc/backends/ops.py\", line 16, in <module>\r\n    from .cblas import CBlas\r\n  File \"thinc/backends/cblas.pyx\", line 1, in init thinc.backends.cblas\r\n  File \"/usr/local/lib/python3.9/dist-packages/blis/__init__.py\", line 3, in <module>\r\n    from .cy import init\r\nImportError: /usr/local/lib/python3.9/dist-packages/blis/cy.cpython-39-arm-linux-gnueabihf.so: undefined symbol: __atomic_load_8\n\n### Your Logs \ud83d\udcd2\n\n```log\r\n<insert your logs here>\r\n```\r\n", "reactions": {"url": "https://api.github.com/repos/Significant-Gravitas/Auto-GPT/issues/2874/reactions", "total_count": 0, "+1": 0, "-1": 0, "laugh": 0, "hooray": 0, "confused": 0, "heart": 0, "rocket": 0, "eyes": 0}, "timeline_url": "https://api.github.com/repos/Significant-Gravitas/Auto-GPT/issues/2874/timeline", "performed_via_github_app": null, "state_reason": null}