{"url": "https://api.github.com/repos/Significant-Gravitas/Auto-GPT/issues/3623", "repository_url": "https://api.github.com/repos/Significant-Gravitas/Auto-GPT", "labels_url": "https://api.github.com/repos/Significant-Gravitas/Auto-GPT/issues/3623/labels{/name}", "comments_url": "https://api.github.com/repos/Significant-Gravitas/Auto-GPT/issues/3623/comments", "events_url": "https://api.github.com/repos/Significant-Gravitas/Auto-GPT/issues/3623/events", "html_url": "https://github.com/Significant-Gravitas/Auto-GPT/issues/3623", "id": 1690826591, "node_id": "I_kwDOJKSTjM5kx_df", "number": 3623, "title": "Auto GPT data_ingestion is not working [lacking workspace_path init]", "user": {"login": "paulofalcao-hub", "id": 115635496, "node_id": "U_kgDOBuR1KA", "avatar_url": "https://avatars.githubusercontent.com/u/115635496?v=4", "gravatar_id": "", "url": "https://api.github.com/users/paulofalcao-hub", "html_url": "https://github.com/paulofalcao-hub", "followers_url": "https://api.github.com/users/paulofalcao-hub/followers", "following_url": "https://api.github.com/users/paulofalcao-hub/following{/other_user}", "gists_url": "https://api.github.com/users/paulofalcao-hub/gists{/gist_id}", "starred_url": "https://api.github.com/users/paulofalcao-hub/starred{/owner}{/repo}", "subscriptions_url": "https://api.github.com/users/paulofalcao-hub/subscriptions", "organizations_url": "https://api.github.com/users/paulofalcao-hub/orgs", "repos_url": "https://api.github.com/users/paulofalcao-hub/repos", "events_url": "https://api.github.com/users/paulofalcao-hub/events{/privacy}", "received_events_url": "https://api.github.com/users/paulofalcao-hub/received_events", "type": "User", "site_admin": false}, "labels": [{"id": 5272676193, "node_id": "LA_kwDOJKSTjM8AAAABOkanYQ", "url": "https://api.github.com/repos/Significant-Gravitas/Auto-GPT/labels/bug", "name": "bug", "color": "d73a4a", "default": true, "description": "Something isn't working"}, {"id": 5405941895, "node_id": "LA_kwDOJKSTjM8AAAABQjgghw", "url": "https://api.github.com/repos/Significant-Gravitas/Auto-GPT/labels/function:%20workspace", "name": "function: workspace", "color": "689805", "default": false, "description": ""}], "state": "open", "locked": false, "assignee": null, "assignees": [], "milestone": null, "comments": 1, "created_at": "2023-05-01T13:45:37Z", "updated_at": "2023-05-01T17:54:20Z", "closed_at": null, "author_association": "NONE", "active_lock_reason": null, "body": "### \u26a0\ufe0f Search for existing issues first \u26a0\ufe0f\n\n- [X] I have searched the existing issues, and there is no existing issue for my problem\n\n### Which Operating System are you using?\n\nWindows\n\n### Which version of Auto-GPT are you using?\n\nStable (branch)\n\n### GPT-3 or GPT-4?\n\nGPT-3.5\n\n### Steps to reproduce \ud83d\udd79\n\n***python data_ingestion.py --dir previous --init --overlap 100 --max_length 2000***\r\n\r\nTraceback (most recent call last):\r\n  File \"C:\\Tools\\openai\\Auto-GPT\\data_ingestion.py\", line 96, in <module>\r\n    main()\r\n  File \"C:\\Tools\\openai\\Auto-GPT\\data_ingestion.py\", line 73, in main\r\n    memory = get_memory(cfg, init=args.init)\r\n  File \"C:\\Tools\\openai\\Auto-GPT\\autogpt\\memory\\__init__.py\", line 78, in get_memory\r\n    memory = LocalCache(cfg)\r\n  File \"C:\\Tools\\openai\\Auto-GPT\\autogpt\\singleton.py\", line 15, in __call__\r\n    cls._instances[cls] = super(Singleton, cls).__call__(*args, **kwargs)\r\n  File \"C:\\Tools\\openai\\Auto-GPT\\autogpt\\memory\\local.py\", line 41, in __init__\r\n    workspace_path = Path(cfg.workspace_path)\r\n  File \"C:\\Program Files\\WindowsApps\\PythonSoftwareFoundation.Python.3.10_3.10.3056.0_x64__qbz5n2kfra8p0\\lib\\pathlib.py\", line 960, in __new__\r\n    self = cls._from_parts(args)\r\n  File \"C:\\Program Files\\WindowsApps\\PythonSoftwareFoundation.Python.3.10_3.10.3056.0_x64__qbz5n2kfra8p0\\lib\\pathlib.py\", line 594, in _from_parts\r\n    drv, root, parts = self._parse_args(args)\r\n  File \"C:\\Program Files\\WindowsApps\\PythonSoftwareFoundation.Python.3.10_3.10.3056.0_x64__qbz5n2kfra8p0\\lib\\pathlib.py\", line 578, in _parse_args\r\n    a = os.fspath(a)\r\nTypeError: expected str, bytes or os.PathLike object, not NoneType\n\n### Current behavior \ud83d\ude2f\n\nDoes not work because the workspace_path is not initialized\n\n### Expected behavior \ud83e\udd14\n\nShould work :)\n\n### Your prompt \ud83d\udcdd\n\ndata_ingestion, it was in the prompt mode. That works.\n\n### Your Logs \ud83d\udcd2\n\nTraceback (most recent call last):\r\n  File \"C:\\Tools\\openai\\Auto-GPT\\data_ingestion.py\", line 96, in <module>\r\n    main()\r\n  File \"C:\\Tools\\openai\\Auto-GPT\\data_ingestion.py\", line 73, in main\r\n    memory = get_memory(cfg, init=args.init)\r\n  File \"C:\\Tools\\openai\\Auto-GPT\\autogpt\\memory\\__init__.py\", line 78, in get_memory\r\n    memory = LocalCache(cfg)\r\n  File \"C:\\Tools\\openai\\Auto-GPT\\autogpt\\singleton.py\", line 15, in __call__\r\n    cls._instances[cls] = super(Singleton, cls).__call__(*args, **kwargs)\r\n  File \"C:\\Tools\\openai\\Auto-GPT\\autogpt\\memory\\local.py\", line 41, in __init__\r\n    workspace_path = Path(cfg.workspace_path)\r\n  File \"C:\\Program Files\\WindowsApps\\PythonSoftwareFoundation.Python.3.10_3.10.3056.0_x64__qbz5n2kfra8p0\\lib\\pathlib.py\", line 960, in __new__\r\n    self = cls._from_parts(args)\r\n  File \"C:\\Program Files\\WindowsApps\\PythonSoftwareFoundation.Python.3.10_3.10.3056.0_x64__qbz5n2kfra8p0\\lib\\pathlib.py\", line 594, in _from_parts\r\n    drv, root, parts = self._parse_args(args)\r\n  File \"C:\\Program Files\\WindowsApps\\PythonSoftwareFoundation.Python.3.10_3.10.3056.0_x64__qbz5n2kfra8p0\\lib\\pathlib.py\", line 578, in _parse_args\r\n    a = os.fspath(a)\r\nTypeError: expected str, bytes or os.PathLike object, not NoneType", "reactions": {"url": "https://api.github.com/repos/Significant-Gravitas/Auto-GPT/issues/3623/reactions", "total_count": 0, "+1": 0, "-1": 0, "laugh": 0, "hooray": 0, "confused": 0, "heart": 0, "rocket": 0, "eyes": 0}, "timeline_url": "https://api.github.com/repos/Significant-Gravitas/Auto-GPT/issues/3623/timeline", "performed_via_github_app": null, "state_reason": null}